<mujoco>
    <size njmax="3000" nconmax="1000"/>
    <option timestep="0.004"/>
    <default>
        <geom condim="6" density="5" rgba="1 0 0 1" size=".05" type="sphere"/>
        <joint damping=".001"/>
        <motor ctrlrange="-1 1" ctrllimited="true" forcerange="-.05 .05" forcelimited="true"/>
        <velocity ctrlrange="0 1" ctrllimited="true" forcerange="-.05 .05" forcelimited="true"/>
        <site size="0.032" type="sphere"/>
    </default>
    <worldbody>
        <geom name="floor" size="5 5 0.1" type="plane" condim="6"/>
        <body name="robot" pos="0 0 .1">
            <site name="robot" pos="0 0 0"/>
            <camera name="vision" pos="0 0.1 .2" xyaxes="-1 0 0 0 -.4 1"/>
            <joint type="free" name="robot" damping="0"/>
            <geom name="robot" type="box" size=".1 .1 .05"/>
            <geom name="back_bumper" type="box" pos="0 .15 0" size=".1 .01 .05"/>
            <geom name="back_connector" type="box" pos="0 .125 0" size=".01 .025 .03"/>
            <body name="left" pos="-.1 .1 -.05">
                <joint type="hinge" name="left" axis="1 0 0"/>
                <geom type="cylinder" name="left" fromto="-.055 0 0 -0.005 0 0"/>
                	<site size=".01" pos=".01 0 .002"/>
			<site size=".01" pos=".01 0 -.002"/>
			<site size=".01" pos="0 0 .002"/>
			<site size=".01" pos="0 0 -.002"/>
            </body>
            <body name="right" pos=".1 .1 -.05">
                <joint type="hinge" name="right" axis="1 0 0"/>
                <geom type="cylinder" name="right" fromto="0.005 0 0 .055 0 0"/>
                	<site size=".01" pos="-.01 0 .002"/>
			<site size=".01" pos="-.01 0 -.002"/>
			<site size=".01" pos="0 0 .002"/>
			<site size=".01" pos="0 0 -.002"/>
            </body>
            <body name="rear" pos="0 -.1 -.05">
            	<joint name="x" type="hinge" axis="0 0 1" limited="true" range="-1 1"/>	        
            	<geom type="ellipsoid" name="rear" fromto="-0.03 0.05 0 .03 0.05 0"/>            	
            </body>
        </body>
    </worldbody>
    <tendon>
    	<fixed name="wheel_rod">
    		<joint joint="left" coef="1"/>
    		<joint joint="right" coef="1"/>
    	</fixed>
    </tendon>
    <sensor>
        <!--<jointvel joint="left" name="jointvel_left"/>
        <jointvel joint="right" name="jointvel_right"/>-->

        
        <!-- Used for observation -->
        <accelerometer site="robot" name="accelerometer"/>
        <velocimeter site="robot" name="velocimeter"/>
        <gyro site="robot" name="gyro"/>
        <magnetometer site="robot" name="magnetometer"/>

        <!-- Used for intrinsic constraints -->
        <subtreecom body="robot" name="subtreecom"/>
        <subtreelinvel body="robot" name="subtreelinvel"/>
        <subtreeangmom body="robot" name="subtreeangmom"/>
    </sensor>
    <actuator>
        <motor gear="0.5 0 0 0 0 0" jointinparent="x" name="rear"/>
        <velocity gear="0.5" tendon="wheel_rod" name="forward"/>
    </actuator>
</mujoco>
